#VRML_SIM R2022a utf8
WorldInfo {
}
Viewpoint {
  orientation -0.5773502691896258 0.5773502691896258 0.5773502691896258 2.0944
  position -1.4965866932507856 0.5006482723879511 4.611577017086366
}
TexturedBackground {
}
RectangleArena {
  floorSize 5 5
}
PointLight {
  attenuation 0 0 1
  location -0.5 0 0
  radius 10
}
PointLight {
  attenuation 0 0 1
  location 0.7 0.2 0
  radius 10
}
PointLight {
  attenuation 0 0 1
  location 0 -1 0
  radius 10
}
Robot {
  translation -1.5 0.5 0.0344654
  rotation 1.2760909691385686e-06 0.9999999999991755 -1.440390651430165e-07 0.09869048287479483
  children [
    LightSensor {
      translation 0.1 0 0
      children [
        Shape {
          appearance PBRAppearance {
            baseColor 0 0 1
          }
          geometry Box {
            size 0.01 0.01 0.01
          }
        }
      ]
      name "ls_center"
    }
    DEF BODY Shape {
      appearance PBRAppearance {
        baseColor 0.917647 0.145098 0.145098
        roughness 1
        metalness 0
      }
      geometry Box {
        size 0.2 0.05 0.05
      }
    }
    DEF WHEEL3 HingeJoint {
      jointParameters HingeJointParameters {
        position 393.85532032683494
        axis 0 1 0
        anchor -0.05 0 0
      }
      device [
        RotationalMotor {
          name "wheel3"
          maxTorque 1000
        }
      ]
      endPoint Solid {
        translation -0.05 0 0
        rotation -0.4189369813733929 0.6420626048565073 -0.6420649632884713 3.9350380927130737
        children [
          DEF WHEEL Shape {
            appearance PBRAppearance {
              baseColor 0.305882 0.898039 0.25098
              roughness 1
              metalness 0
            }
            geometry Cylinder {
              height 0.02
              radius 0.04
              subdivision 24
            }
          }
        ]
        name "solid(2)"
        boundingObject DEF WHEEL Shape {
          appearance PBRAppearance {
            baseColor 0.305882 0.898039 0.25098
            roughness 1
            metalness 0
          }
          geometry Cylinder {
            height 0.02
            radius 0.04
            subdivision 24
          }
        }
        physics Physics {
        }
      }
    }
    DEF DS_LEFT DistanceSensor {
      translation 0.1 0.03 0
      rotation 0 0 1 0.3
      children [
        Shape {
          appearance PBRAppearance {
            baseColor 0.184314 0.596078 0.847059
            roughness 1
            metalness 0
          }
          geometry Box {
            size 0.01 0.01 0.01
          }
        }
      ]
      name "ds_left"
    }
  ]
  boundingObject USE BODY
  physics Physics {
    density -1
    mass 1
  }
  controller "braitenberg_vehicle"
}
