#VRML_SIM R2022a utf8
WorldInfo {
}
Viewpoint {
  orientation -0.5773502691896258 0.5773502691896258 0.5773502691896258 2.0944
  position -1.4684228560469433e-05 -1.468427008440464e-05 7.488183825102065
}
TexturedBackground {
}
RectangleArena {
  floorSize 5 5
}
Robot {
  translation 2.4001392504983254 -0.49926902891117086 0.039720854449879675
  rotation 0.9999994824751349 -0.0007193869126464596 0.0007193969225160915 1.570796623581447
  children [
    DEF BODY Shape {
      appearance PBRAppearance {
        baseColor 0.917647 0.145098 0.145098
        roughness 1
        metalness 0
      }
      geometry Box {
        size 0.2 0.05 0.1
      }
    }
    DEF WHEEL1 HingeJoint {
      jointParameters HingeJointParameters {
        position -1343.6464174181774
        axis 0 0 1
        anchor 0.06 0 0.05
      }
      endPoint Solid {
        translation 0.06 0 0.05
        rotation 0 0 1 0.9552383182540992
        children [
          DEF WHEEL Transform {
            rotation 0 0 1 1.5708
            children [
              Shape {
                appearance PBRAppearance {
                  baseColor 0.305882 0.898039 0.25098
                  roughness 1
                  metalness 0
                }
                geometry Cylinder {
                  height 0.02
                  radius 0.04
                  subdivision 24
                }
              }
            ]
          }
        ]
        boundingObject USE WHEEL
        physics Physics {
        }
        linearVelocity -9.698145921138695e-10 -1.569374822516813e-10 7.178999495095825e-09
        angularVelocity 1.2502687435552943e-08 7.761450729758993e-08 -6.25991525256693e-10
      }
    }
    DEF WHEEL2 HingeJoint {
      jointParameters HingeJointParameters {
        position -2120.3706415725633
        axis 0 0 1
        anchor -0.06 0 0.05
      }
      device [
        RotationalMotor {
          name "wheel2"
        }
      ]
      endPoint Solid {
        translation -0.06 0 0.05
        rotation 0 0 1 3.3459922541369567
        children [
          USE WHEEL
        ]
        name "solid(1)"
        boundingObject USE WHEEL
        physics Physics {
        }
        linearVelocity -9.435383085041245e-10 -8.23473357240261e-11 -1.8141328623103847e-09
        angularVelocity 2.6730246580110227e-09 0.9999985461410026 -2.215759273106096e-07
      }
    }
    DEF WHEEL3 HingeJoint {
      jointParameters HingeJointParameters {
        position -1331.0061432691134
        axis 0 0 1
        anchor 0.06 0 -0.05
      }
      endPoint Solid {
        translation 0.06 0 -0.05
        rotation 0 0 1 1.0291418529589245
        children [
          USE WHEEL
        ]
        name "solid(2)"
        boundingObject USE WHEEL
        physics Physics {
        }
        linearVelocity -9.187859848414477e-10 -1.5693724079495998e-10 8.415061040736232e-09
        angularVelocity 1.2502703901406824e-08 9.370307006886075e-08 -6.259910631742626e-10
      }
    }
    DEF WHEEL4 HingeJoint {
      jointParameters HingeJointParameters {
        position -2065.8853891230433
        axis 0 0 1
        anchor -0.06 0 -0.05
      }
      device [
        RotationalMotor {
          name "wheel4"
        }
      ]
      endPoint Solid {
        translation -0.06 0 -0.05
        rotation 0 0 -1 5.000608368138932
        children [
          USE WHEEL
        ]
        name "solid(3)"
        boundingObject USE WHEEL
        physics Physics {
        }
        linearVelocity -8.811462948048722e-10 -8.234705976574922e-11 -5.884026358344996e-10
        angularVelocity 2.6730181649140555e-09 0.9999985461401798 -2.2157592827269945e-07
      }
    }
    LightSensor {
      translation 0.1 0 0.03
      children [
        Shape {
          appearance PBRAppearance {
            baseColor 0 0 1
            roughness 1
            metalness 0
          }
          geometry Box {
            size 0.01 0.01 0.01
          }
        }
      ]
      name "ls_left"
      lookupTable [
        0 0 0
        1 100 0
        10 1000 0
      ]
    }
    LightSensor {
      translation 0.1 0 -0.03
      children [
        Shape {
          appearance PBRAppearance {
            baseColor 0 0 1
            roughness 1
            metalness 0
          }
          geometry Box {
            size 0.01 0.01 0.01
          }
        }
      ]
      name "ls_right"
      lookupTable [
        0 0 0
        1 100 0
        10 1000 0
      ]
    }
  ]
  boundingObject USE BODY
  physics Physics {
    density -1
    mass 1
  }
  controller "braitenberg_vehicle"
  linearVelocity -9.190202021613914e-10 -1.2137458905395626e-10 3.345043978697504e-09
  angularVelocity 1.2502453537861897e-08 -7.617236862694933e-08 -6.258187750008308e-10
}
PointLight {
  attenuation 0 0 12.56
  intensity 100
  location 0.5 0 0
  castShadows TRUE
}
TexturedBackgroundLight {
}
